<?xml version="1.0" encoding="utf-8"?>
<!-- This URDF was automatically created by SolidWorks to URDF Exporter! Originally created by Stephen Brawner (brawner@gmail.com) 
     Commit Version: 1.6.0-1-g15f4949  Build Version: 1.6.7594.29634
     For more information, please see http://wiki.ros.org/sw_urdf_exporter -->
<robot
  name="hopper_rev10">
  <link
    name="base_link">
    <inertial>
      <origin
        xyz="-0.00418073480569239 1.97542028309751E-05 0.0166947584700169"
        rpy="0 0 0" />
      <mass
        value="4.74655621241113" />
      <inertia
        ixx="0.00384817967874738"
        ixy="-3.77803105397745E-06"
        ixz="0.000170614090606966"
        iyy="0.00499115256258607"
        iyz="6.51253420197333E-06"
        izz="0.00368599412915382" />
    </inertial>
    <visual>
      <origin
        xyz="0 0 0"
        rpy="0 0 0" />
      <geometry>
        <mesh
          filename="package://hopper_rev10/meshes/base_link.STL" />
      </geometry>
      <material
        name="">
        <color
          rgba="0.752941176470588 0.752941176470588 0.752941176470588 1" />
      </material>
    </visual>
    <collision>
      <origin
        xyz="0 0 0"
        rpy="0 0 0" />
      <geometry>
        <mesh
          filename="package://hopper_rev10/meshes/base_link.STL" />
      </geometry>
    </collision>
  </link>
  <link
    name="Link 0">
    <inertial>
      <origin
        xyz="0.00533298750981774 0.0313630772301346 0.000493209394940068"
        rpy="0 0 0" />
      <mass
        value="0.585807373885291" />
      <inertia
        ixx="0.000227450651738696"
        ixy="1.53797540461376E-05"
        ixz="-8.48627409122145E-06"
        iyy="0.000542253205909838"
        iyz="1.08266324119426E-06"
        izz="0.000337811683144688" />
    </inertial>
    <visual>
      <origin
        xyz="0 0 0"
        rpy="0 0 0" />
      <geometry>
        <mesh
          filename="package://hopper_rev10/meshes/Link 0.STL" />
      </geometry>
      <material
        name="">
        <color
          rgba="0.752941176470588 0.752941176470588 0.752941176470588 1" />
      </material>
    </visual>
    <collision>
      <origin
        xyz="0 0 0"
        rpy="0 0 0" />
      <geometry>
        <mesh
          filename="package://hopper_rev10/meshes/Link 0.STL" />
      </geometry>
    </collision>
  </link>
  <joint
    name="Joint 0"
    type="revolute">
    <origin
      xyz="0 0 0"
      rpy="0 0.523598775598294 0" />
    <parent
      link="base_link" />
    <child
      link="Link 0" />
    <axis
      xyz="0 -1 0" />
    <limit
      lower="-3.14"
      upper="3.14"
      effort="0"
      velocity="0" />
  </joint>
  <link
    name="Link 1">
    <inertial>
      <origin
        xyz="0.13539209115605 0.00693719848430879 5.37951665158243E-09"
        rpy="0 0 0" />
      <mass
        value="0.0809765946737082" />
      <inertia
        ixx="3.67055430414587E-06"
        ixy="1.75781402022514E-12"
        ixz="-8.38012013331757E-13"
        iyy="0.000575385419066408"
        iyz="-1.84543378097518E-12"
        izz="0.000572662360554517" />
    </inertial>
    <visual>
      <origin
        xyz="0 0 0"
        rpy="0 0 0" />
      <geometry>
        <mesh
          filename="package://hopper_rev10/meshes/Link 1.STL" />
      </geometry>
      <material
        name="">
        <color
          rgba="0.752941176470588 0.752941176470588 0.752941176470588 1" />
      </material>
    </visual>
    <collision>
      <origin
        xyz="0 0 0"
        rpy="0 0 0" />
      <geometry>
        <mesh
          filename="package://hopper_rev10/meshes/Link 1.STL" />
      </geometry>
    </collision>
  </link>
  <joint
    name="Joint 1"
    type="revolute">
    <origin
      xyz="0.0999999999999999 0 0"
      rpy="3.14159265358979 1.0471975511966 3.14159265358979" />
    <parent
      link="Link 0" />
    <child
      link="Link 1" />
    <axis
      xyz="0 -1 0" />
    <limit
      lower="-0.7597"
      upper="1.8295"
      effort="0"
      velocity="0" />
  </joint>
  <link
    name="Link 2">
    <inertial>
      <origin
        xyz="0.0385293506057188 -0.0274403245603329 -7.28006543602791E-05"
        rpy="0 0 0" />
      <mass
        value="0.734902377684507" />
      <inertia
        ixx="0.000249183690679803"
        ixy="-3.6482173551612E-06"
        ixz="5.99874903328178E-05"
        iyy="0.00272626632220472"
        iyz="7.05852172253244E-09"
        izz="0.0025027134961882" />
    </inertial>
    <visual>
      <origin
        xyz="0 0 0"
        rpy="0 0 0" />
      <geometry>
        <mesh
          filename="package://hopper_rev10/meshes/Link 2.STL" />
      </geometry>
      <material
        name="">
        <color
          rgba="0.752941176470588 0.752941176470588 0.752941176470588 1" />
      </material>
    </visual>
    <collision>
      <origin
        xyz="0 0 0"
        rpy="0 0 0" />
      <geometry>
        <mesh
          filename="package://hopper_rev10/meshes/Link 2.STL" />
      </geometry>
    </collision>
  </link>
  <joint
    name="Joint 2"
    type="revolute">
    <origin
      xyz="0 0 0"
      rpy="3.14159265358979 0.523598775598307 3.14159265358979" />
    <parent
      link="base_link" />
    <child
      link="Link 2" />
    <axis
      xyz="0 -1 0" />
    <limit
      lower="-3.14"
      upper="3.14"
      effort="0"
      velocity="0" />
  </joint>
  <link
    name="Link 3">
    <inertial>
      <origin
        xyz="0.125790519058872 8.30702454964866E-06 -0.0172727967261267"
        rpy="0 0 0" />
      <mass
        value="0.155003240845989" />
      <inertia
        ixx="0.000133829959920236"
        ixy="1.64589026469064E-06"
        ixz="1.71252935488417E-05"
        iyy="0.000401608454807521"
        iyz="7.44886185264235E-08"
        izz="0.000510583013209461" />
    </inertial>
    <visual>
      <origin
        xyz="0 0 0"
        rpy="0 0 0" />
      <geometry>
        <mesh
          filename="package://hopper_rev10/meshes/Link 3.STL" />
      </geometry>
      <material
        name="">
        <color
          rgba="0.752941176470588 0.752941176470588 0.752941176470588 1" />
      </material>
    </visual>
    <collision>
      <origin
        xyz="0 0 0"
        rpy="0 0 0" />
      <geometry>
        <mesh
          filename="package://hopper_rev10/meshes/Link 3.STL" />
      </geometry>
    </collision>
  </link>
  <joint
    name="Joint 3"
    type="revolute">
    <origin
      xyz="0.27 0 0"
      rpy="-3.14159265358979 -1.0471975511966 3.14159265358979" />
    <parent
      link="Link 2" />
    <child
      link="Link 3" />
    <axis
      xyz="0 -1 0" />
    <limit
      lower="-1.8295"
      upper="0.7597"
      effort="0"
      velocity="0" />
  </joint>
  <link
    name="rw0">
    <inertial>
      <origin
        xyz="-0.0112089109898321 3.32852800877248E-10 1.96059004119169E-09"
        rpy="0 0 0" />
      <mass
        value="0.782030273721286" />
      <inertia
        ixx="0.00650606752550228"
        ixy="-1.48647131929802E-12"
        ixz="3.14929314168687E-12"
        iyy="0.00327830021020953"
        iyz="-2.52228157608994E-11"
        izz="0.00327830030688908" />
    </inertial>
    <visual>
      <origin
        xyz="0 0 0"
        rpy="0 0 0" />
      <geometry>
        <mesh
          filename="package://hopper_rev10/meshes/rw0.STL" />
      </geometry>
      <material
        name="">
        <color
          rgba="0.752941176470588 0.752941176470588 0.752941176470588 1" />
      </material>
    </visual>
    <collision>
      <origin
        xyz="0 0 0"
        rpy="0 0 0" />
      <geometry>
        <mesh
          filename="package://hopper_rev10/meshes/rw0.STL" />
      </geometry>
    </collision>
  </link>
  <joint
    name="joint_rw0"
    type="continuous">
    <origin
      xyz="0.056569 -0.1372 0"
      rpy="0 0 -0.7854" />
    <parent
      link="base_link" />
    <child
      link="rw0" />
    <axis
      xyz="-1 0 0" />
  </joint>
  <link
    name="rw1">
    <inertial>
      <origin
        xyz="-0.0112089109884331 3.25952910495975E-10 1.94954457698549E-09"
        rpy="0 0 0" />
      <mass
        value="0.78203027385753" />
      <inertia
        ixx="0.00650606752666634"
        ixy="-1.46849297045365E-12"
        ixz="3.18349661661483E-12"
        iyy="0.00327830021088511"
        iyz="-2.55083136067597E-11"
        izz="0.00327830030737773" />
    </inertial>
    <visual>
      <origin
        xyz="0 0 0"
        rpy="0 0 0" />
      <geometry>
        <mesh
          filename="package://hopper_rev10/meshes/rw1.STL" />
      </geometry>
      <material
        name="">
        <color
          rgba="0.752941176470588 0.752941176470588 0.752941176470588 1" />
      </material>
    </visual>
    <collision>
      <origin
        xyz="0 0 0"
        rpy="0 0 0" />
      <geometry>
        <mesh
          filename="package://hopper_rev10/meshes/rw1.STL" />
      </geometry>
    </collision>
  </link>
  <joint
    name="joint_rw1"
    type="continuous">
    <origin
      xyz="0.056569 0.1372 0"
      rpy="0 0 0.7854" />
    <parent
      link="base_link" />
    <child
      link="rw1" />
    <axis
      xyz="-1 0 0" />
  </joint>
  <link
    name="rwz">
    <inertial>
      <origin
        xyz="-0.0085978961747486 1.39122333027781E-09 -1.07114626890503E-09"
        rpy="0 0 0" />
      <mass
        value="0.329527985190625" />
      <inertia
        ixx="0.000788032746166235"
        ixy="-3.22938025750919E-13"
        ixz="9.51697818180561E-13"
        iyy="0.00039873558860043"
        iyz="2.16854596668185E-13"
        izz="0.000398735588352925" />
    </inertial>
    <visual>
      <origin
        xyz="0 0 0"
        rpy="0 0 0" />
      <geometry>
        <mesh
          filename="package://hopper_rev10/meshes/rwz.STL" />
      </geometry>
      <material
        name="">
        <color
          rgba="0.752941176470588 0.752941176470588 0.752941176470588 1" />
      </material>
    </visual>
    <collision>
      <origin
        xyz="0 0 0"
        rpy="0 0 0" />
      <geometry>
        <mesh
          filename="package://hopper_rev10/meshes/rwz.STL" />
      </geometry>
    </collision>
  </link>
  <joint
    name="joint_rwz"
    type="continuous">
    <origin
      xyz="-0.076 0 0.086"
      rpy="3.1416 -1.5708 0" />
    <parent
      link="base_link" />
    <child
      link="rwz" />
    <axis
      xyz="-1 0 0" />
  </joint>
</robot>