<?xml version="1.0" encoding="utf-8"?>
<!-- This URDF was automatically created by SolidWorks to URDF Exporter! Originally created by Stephen Brawner (brawner@gmail.com) 
     Commit Version: 1.6.0-4-g7f85cfe  Build Version: 1.6.7995.38578
     For more information, please see http://wiki.ros.org/sw_urdf_exporter -->
<robot
  name="hopper_rev09">
  <link
    name="base_link">
    <inertial>
      <origin
        xyz="-0.0033904551236681 2.01175227818367E-05 0.0165845358018971"
        rpy="0 0 0" />
      <mass
        value="4.7828220563841" />
      <inertia
        ixx="0.00403695378673249"
        ixy="-3.62904611186374E-06"
        ixz="0.000181371071322505"
        iyy="0.00524134884989508"
        iyz="6.42651713008798E-06"
        izz="0.0037477949793726" />
    </inertial>
    <visual>
      <origin
        xyz="0 0 0"
        rpy="0 0 0" />
      <geometry>
        <mesh
          filename="package://hopper_rev09/meshes/base_link.STL" />
      </geometry>
      <material
        name="">
        <color
          rgba="0.752941176470588 0.752941176470588 0.752941176470588 1" />
      </material>
    </visual>
    <collision>
      <origin
        xyz="0 0 0"
        rpy="0 0 0" />
      <geometry>
        <mesh
          filename="package://hopper_rev09/meshes/base_link.STL" />
      </geometry>
    </collision>
  </link>
  <link
    name="Link 0">
    <inertial>
      <origin
        xyz="0.00533298750981788 0.0313630772301307 0.000493209394939516"
        rpy="0 0 0" />
      <mass
        value="0.585807373885291" />
      <inertia
        ixx="0.000227450651738696"
        ixy="1.53797540461375E-05"
        ixz="-8.48627409122185E-06"
        iyy="0.000542253205909839"
        iyz="1.08266324119401E-06"
        izz="0.000337811683144689" />
    </inertial>
    <visual>
      <origin
        xyz="0 0 0"
        rpy="0 0 0" />
      <geometry>
        <mesh
          filename="package://hopper_rev09/meshes/Link 0.STL" />
      </geometry>
      <material
        name="">
        <color
          rgba="0.752941176470588 0.752941176470588 0.752941176470588 1" />
      </material>
    </visual>
    <collision>
      <origin
        xyz="0 0 0"
        rpy="0 0 0" />
      <geometry>
        <mesh
          filename="package://hopper_rev09/meshes/Link 0.STL" />
      </geometry>
    </collision>
  </link>
  <joint
    name="Joint 0"
    type="revolute">
    <origin
      xyz="0 0 0"
      rpy="0 0.523598775598299 0" />
    <parent
      link="base_link" />
    <child
      link="Link 0" />
    <axis
      xyz="0 -1 0" />
    <limit
      lower="-3.14"
      upper="3.14"
      effort="0"
      velocity="0" />
  </joint>
  <link
    name="Link 1">
    <inertial>
      <origin
        xyz="0.116031386986065 0.00693719848430448 0.0697691592445978"
        rpy="0 0 0" />
      <mass
        value="0.0809765946737085" />
      <inertia
        ixx="0.000154764250027393"
        ixy="2.45742668183085E-12"
        ixz="-0.00025128026177021"
        iyy="0.000575385419066409"
        iyz="-6.75718506791511E-13"
        izz="0.000421568664831271" />
    </inertial>
    <visual>
      <origin
        xyz="0 0 0"
        rpy="0 0 0" />
      <geometry>
        <mesh
          filename="package://hopper_rev09/meshes/Link 1.STL" />
      </geometry>
      <material
        name="">
        <color
          rgba="0.752941176470588 0.752941176470588 0.752941176470588 1" />
      </material>
    </visual>
    <collision>
      <origin
        xyz="0 0 0"
        rpy="0 0 0" />
      <geometry>
        <mesh
          filename="package://hopper_rev09/meshes/Link 1.STL" />
      </geometry>
    </collision>
  </link>
  <joint
    name="Joint 1"
    type="revolute">
    <origin
      xyz="0.1 0 0"
      rpy="-3.14159265358979 0.505826008429944 3.14159265358979" />
    <parent
      link="Link 0" />
    <child
      link="Link 1" />
    <axis
      xyz="0 -1 0" />
    <limit
      lower="-0.7597"
      upper="1.8295"
      effort="0"
      velocity="0" />
  </joint>
  <link
    name="Link 2">
    <inertial>
      <origin
        xyz="0.0385293506057193 -0.0274403245603325 -7.28006543603034E-05"
        rpy="0 0 0" />
      <mass
        value="0.734902377684508" />
      <inertia
        ixx="0.000249183690679803"
        ixy="-3.64821735516121E-06"
        ixz="5.99874903328164E-05"
        iyy="0.00272626632220471"
        iyz="7.05852172252969E-09"
        izz="0.0025027134961882" />
    </inertial>
    <visual>
      <origin
        xyz="0 0 0"
        rpy="0 0 0" />
      <geometry>
        <mesh
          filename="package://hopper_rev09/meshes/Link 2.STL" />
      </geometry>
      <material
        name="">
        <color
          rgba="0.752941176470588 0.752941176470588 0.752941176470588 1" />
      </material>
    </visual>
    <collision>
      <origin
        xyz="0 0 0"
        rpy="0 0 0" />
      <geometry>
        <mesh
          filename="package://hopper_rev09/meshes/Link 2.STL" />
      </geometry>
    </collision>
  </link>
  <joint
    name="Joint 2"
    type="revolute">
    <origin
      xyz="0 0 0"
      rpy="3.14159265358979 0.523598775598306 3.14159265358979" />
    <parent
      link="base_link" />
    <child
      link="Link 2" />
    <axis
      xyz="0 -1 0" />
    <limit
      lower="-3.14"
      upper="3.14"
      effort="0"
      velocity="0" />
  </joint>
  <link
    name="Link 3">
    <inertial>
      <origin
        xyz="-0.00096013225385333 1.19207215622385E-05 -0.142163027382135"
        rpy="0 0 0" />
      <mass
        value="0.108053074640562" />
      <inertia
        ixx="0.000389507294892826"
        ixy="2.0877211229001E-07"
        ixz="1.36817326630028E-05"
        iyy="0.00039718722729753"
        iyz="-1.63429778221469E-06"
        izz="1.36148548407447E-05" />
    </inertial>
    <visual>
      <origin
        xyz="0 0 0"
        rpy="0 0 0" />
      <geometry>
        <mesh
          filename="package://hopper_rev09/meshes/Link 3.STL" />
      </geometry>
      <material
        name="">
        <color
          rgba="0.752941176470588 0.752941176470588 0.752941176470588 1" />
      </material>
    </visual>
    <collision>
      <origin
        xyz="0 0 0"
        rpy="0 0 0" />
      <geometry>
        <mesh
          filename="package://hopper_rev09/meshes/Link 3.STL" />
      </geometry>
    </collision>
  </link>
  <joint
    name="Joint 3"
    type="revolute">
    <origin
      xyz="0.27 0 0"
      rpy="-3.14159265358979 0.441767558289077 -3.14159265358979" />
    <parent
      link="Link 2" />
    <child
      link="Link 3" />
    <axis
      xyz="0 -1 0" />
    <limit
      lower="-1.8295"
      upper="0.7597"
      effort="0"
      velocity="0" />
  </joint>
  <link
    name="rw0">
    <inertial>
      <origin
        xyz="0.00252831847155865 -1.31056414952576E-09 -0.00252831711451848"
        rpy="0 0 0" />
      <mass
        value="0.710071298141227" />
      <inertia
        ixx="0.00266424528769832"
        ixy="1.32410998715932E-11"
        ixz="-0.000872537148608607"
        iyy="0.00179170800683662"
        iyz="4.36237508666819E-12"
        izz="0.002664245284981" />
    </inertial>
    <visual>
      <origin
        xyz="0 0 0"
        rpy="0 0 0" />
      <geometry>
        <mesh
          filename="package://hopper_rev09/meshes/rw0.STL" />
      </geometry>
      <material
        name="">
        <color
          rgba="0.752941176470588 0.752941176470588 0.752941176470588 1" />
      </material>
    </visual>
    <collision>
      <origin
        xyz="0 0 0"
        rpy="0 0 0" />
      <geometry>
        <mesh
          filename="package://hopper_rev09/meshes/rw0.STL" />
      </geometry>
    </collision>
  </link>
  <joint
    name="joint_rw0"
    type="continuous">
    <origin
      xyz="0.0509116970842678 -0.131539114082235 0"
      rpy="1.5707963267949 0 1.5707963267949" />
    <parent
      link="base_link" />
    <child
      link="rw0" />
    <axis
      xyz="0.70710678118654 0 -0.707106781186555" />
  </joint>
  <link
    name="rw1">
    <inertial>
      <origin
        xyz="0.0738392240897933 -1.30681966451641E-09 0.0738392227417098"
        rpy="0 0 0" />
      <mass
        value="0.710071298067979" />
      <inertia
        ixx="0.00266424528444578"
        ixy="4.47631735085124E-12"
        ixz="0.000872537148756898"
        iyy="0.00179170800713326"
        iyz="-1.33618423617129E-11"
        izz="0.00266424528714435" />
    </inertial>
    <visual>
      <origin
        xyz="0 0 0"
        rpy="0 0 0" />
      <geometry>
        <mesh
          filename="package://hopper_rev09/meshes/rw1.STL" />
      </geometry>
      <material
        name="">
        <color
          rgba="0.752941176470588 0.752941176470588 0.752941176470588 1" />
      </material>
    </visual>
    <collision>
      <origin
        xyz="0 0 0"
        rpy="0 0 0" />
      <geometry>
        <mesh
          filename="package://hopper_rev09/meshes/rw1.STL" />
      </geometry>
    </collision>
  </link>
  <joint
    name="joint_rw1"
    type="continuous">
    <origin
      xyz="-0.025456 0.055172 0"
      rpy="1.5708 0 1.5708" />
    <parent
      link="base_link" />
    <child
      link="rw1" />
    <axis
      xyz="-0.70711 0 -0.70711" />
  </joint>
  <link
    name="rwz">
    <inertial>
      <origin
        xyz="1.3912E-09 0.025902 1.0711E-09"
        rpy="0 0 0" />
      <mass
        value="0.32953" />
      <inertia
        ixx="0.00039874"
        ixy="-3.2294E-13"
        ixz="-2.1685E-13"
        iyy="0.00078803"
        iyz="-9.517E-13"
        izz="0.00039874" />
    </inertial>
    <visual>
      <origin
        xyz="0 0 0"
        rpy="0 0 0" />
      <geometry>
        <mesh
          filename="package://hopper_rev09/meshes/rwz.STL" />
      </geometry>
      <material
        name="">
        <color
          rgba="0.75294 0.75294 0.75294 1" />
      </material>
    </visual>
    <collision>
      <origin
        xyz="0 0 0"
        rpy="0 0 0" />
      <geometry>
        <mesh
          filename="package://hopper_rev09/meshes/rwz.STL" />
      </geometry>
    </collision>
  </link>
  <joint
    name="joint_rwz"
    type="continuous">
    <origin
      xyz="-0.076 0 0.0515"
      rpy="1.5708 0 1.5708" />
    <parent
      link="base_link" />
    <child
      link="rwz" />
    <axis
      xyz="0 -1 0" />
  </joint>
</robot>